<?xml version="1.0" ?>
<!-- =================================================================================== -->
<!-- |    This document was autogenerated by xacro from RM_decription.urdf                  | -->
<!-- |    EDITING THIS FILE BY HAND IS NOT RECOMMENDED                                 | -->
<!-- =================================================================================== -->
<robot xmlns:xacro="http://www.ros.org/wiki/xacro">
<xacro:macro name="arm" params="prefix">
<xacro:include filename="$(find rm_description)/urdf/rm.transmission.xacro"/>
<xacro:include filename="$(find rm_description)/urdf/rm.gazebo.xacro"/>
<xacro:include filename="$(find rm_description)/urdf/common.gazebo.xacro"/>
<!-- Inertial matrix -->
<xacro:macro name="inertial_matrix" params="mass">
    <mass value="${mass}" />
    <inertia ixx="1.0" ixy="0.0" ixz="0.0" iyy="0.5" iyz="0.0" izz="1.0" />
</xacro:macro>

<link
    name="base_link">
    <inertial>
      <origin
        xyz="-0.000109373565465087 -0.000540506855878586 0.0596939182288847"
        rpy="0 0 0" />
      <xacro:inertial_matrix mass="1.0"/>
    </inertial>
    <visual>
      <origin
        xyz="0 0 0"
        rpy="0 0 0" />
      <geometry>
        <mesh
          filename="package://rm_description/meshes/base_link.STL" />
      </geometry>
      <material
        name="">
        <color
          rgba="1 1 1 1" />
      </material>
    </visual>
    <collision>
      <origin
        xyz="0 0 0"
        rpy="0 0 0" />
      <geometry>
        <mesh
          filename="package://rm_description/meshes/base_link.STL" />
      </geometry>
    </collision>
  </link>
  <link
    name="link1">
    <inertial>
      <origin
        xyz="1.03803520729029E-06 -0.0103990426169562 0.0743349525008567"
        rpy="0 0 0" />
      <xacro:inertial_matrix mass="1.0"/>
    </inertial>
    <visual>
      <origin
        xyz="0 0 0"
        rpy="0 0 0" />
      <geometry>
        <mesh
          filename="package://rm_description/meshes/link1.STL" />
      </geometry>
      <material
        name="">
        <color
          rgba="1 1 1 1" />
      </material>
    </visual>
    <collision>
      <origin
        xyz="0 0 0"
        rpy="0 0 0" />
      <geometry>
        <mesh
          filename="package://rm_description/meshes/link1.STL" />
      </geometry>
    </collision>
  </link>
  <joint
    name="joint1"
    type="revolute">
    <origin
      xyz="0 0 0.1327"
      rpy="3.4694E-18 2.4378E-13 -3.1416" />
    <parent
      link="base_link" />
    <child
      link="link1" />
    <axis
      xyz="0 0 1" />
    <limit
      lower="-3.05"
      upper="3.05"
      effort="300"
      velocity="3.14" />
	<dynamics damping="50" friction="1"/>
  </joint>
  <link
    name="link2">
    <inertial>
      <origin
        xyz="0.125617616072843 0.00357568268785996 0.0132826613843138"
        rpy="0 0 0" />
      <xacro:inertial_matrix mass="1.0"/>
    </inertial>
    <visual>
      <origin
        xyz="0 0 0"
        rpy="0 0 0" />
      <geometry>
        <mesh
          filename="package://rm_description/meshes/link2.STL" />
      </geometry>
      <material
        name="">
        <color
          rgba="1 1 1 1" />
      </material>
    </visual>
    <collision>
      <origin
        xyz="0 0 0"
        rpy="0 0 0" />
      <geometry>
        <mesh
          filename="package://rm_description/meshes/link2.STL" />
      </geometry>
    </collision>
  </link>
  <joint
    name="joint2"
    type="revolute">
    <origin
      xyz="0 0.01355 0.1193"
      rpy="-3.1343 -1.5708 -1.5562" />
    <parent
      link="link1" />
    <child
      link="link2" />
    <axis
      xyz="0 0 -1" />
    <limit
      lower="-2"
      upper="2"
      effort="300"
      velocity="3.14" />
	<dynamics damping="50" friction="1"/>
  </joint>
  <link
    name="link3">
    <inertial>
      <origin
        xyz="-2.62322173649743E-07 -0.0531866163941078 0.00185294381389689"
        rpy="0 0 0" />
      <xacro:inertial_matrix mass="1.0"/>
    </inertial>
    <visual>
      <origin
        xyz="0 0 0"
        rpy="0 0 0" />
      <geometry>
        <mesh
          filename="package://rm_description/meshes/link3.STL" />
      </geometry>
      <material
        name="">
        <color
          rgba="1 1 1 1" />
      </material>
    </visual>
    <collision>
      <origin
        xyz="0 0 0"
        rpy="0 0 0" />
      <geometry>
        <mesh
          filename="package://rm_description/meshes/link3.STL" />
      </geometry>
    </collision>
  </link>
  <joint
    name="joint3"
    type="revolute">
    <origin
      xyz="0.2464 0.007 0.0015"
      rpy="-1.7347E-18 -5.5511E-17 1.5708" />
    <parent
      link="link2" />
    <child
      link="link3" />
    <axis
      xyz="0 0 -1" />
    <limit
      lower="-2"
      upper="2"
      effort="300"
      velocity="3.14" />
	<dynamics damping="50" friction="1"/>
  </joint>
  <link
    name="link4">
    <inertial>
      <origin
        xyz="-1.89389405602647E-07 0.0125575326860273 0.0583180851477226"
        rpy="0 0 0" />
      <xacro:inertial_matrix mass="0.1"/>
    </inertial>
    <visual>
      <origin
        xyz="0 0 0"
        rpy="0 0 0" />
      <geometry>
        <mesh
          filename="package://rm_description/meshes/link4.STL" />
      </geometry>
      <material
        name="">
        <color
          rgba="1 1 1 1" />
      </material>
    </visual>
    <collision>
      <origin
        xyz="0 0 0"
        rpy="0 0 0" />
      <geometry>
        <mesh
          filename="package://rm_description/meshes/link4.STL" />
      </geometry>
    </collision>
  </link>
  <joint
    name="joint4"
    type="revolute">
    <origin
      xyz="0 -0.1304 0.01745"
      rpy="1.5708 -5.5511E-17 1.7347E-18" />
    <parent
      link="link3" />
    <child
      link="link4" />
    <axis
      xyz="0 0 1" />
    <limit
      lower="-3.05"
      upper="3.05"
      effort="300"
      velocity="3.14" />
	<dynamics damping="50" friction="1"/>
  </joint>
  <link
    name="link5">
    <inertial>
      <origin
        xyz="-2.3157236272997E-07 -0.0507443613513162 0.00177089430075761"
        rpy="0 0 0" />
      <xacro:inertial_matrix mass="0.1"/>
    </inertial>
    <visual>
      <origin
        xyz="0 0 0"
        rpy="0 0 0" />
      <geometry>
        <mesh
          filename="package://rm_description/meshes/link5.STL" />
      </geometry>
      <material
        name="">
        <color
          rgba="1 1 1 1" />
      </material>
    </visual>
    <collision>
      <origin
        xyz="0 0 0"
        rpy="0 0 0" />
      <geometry>
        <mesh
          filename="package://rm_description/meshes/link5.STL" />
      </geometry>
    </collision>
  </link>
  <joint
    name="joint5"
    type="revolute">
    <origin
      xyz="0 -0.0142 0.0872"
      rpy="-1.5708 1.7347E-18 5.5511E-17" />
    <parent
      link="link4" />
    <child
      link="link5" />
    <axis
      xyz="0 0 -1" />
    <limit
      lower="-2"
      upper="2"
      effort="300"
      velocity="3.14" />
	<dynamics damping="50" friction="1"/>
  </joint>
  <link
    name="link6">
    <inertial>
      <origin
        xyz="-0.000457792901041587 8.72837963215023E-05 -0.012860781989493"
        rpy="0 0 0" />
      <xacro:inertial_matrix mass="0.1"/>
    </inertial>
    <visual>
      <origin
        xyz="0 0 0"
        rpy="0 0 0" />
      <geometry>
        <mesh
          filename="package://rm_description/meshes/link6.STL" />
      </geometry>
      <material
        name="">
        <color
          rgba="1 1 1 1" />
      </material>
    </visual>
    <collision>
      <origin
        xyz="0 0 0"
        rpy="0 0 0" />
      <geometry>
        <mesh
          filename="package://rm_description/meshes/link6.STL" />
      </geometry>
    </collision>
  </link>
  <joint
    name="joint6"
    type="revolute">
    <origin
      xyz="0 -0.1471 0.0146"
      rpy="1.5708 -7.8126E-13 -2.4378E-13" />
    <parent
      link="link5" />
    <child
      link="link6" />
    <axis
      xyz="0 0 1" />
    <limit
      lower="-6.28"
      upper="6.28"
      effort="300"
      velocity="1" />
	<dynamics damping="50" friction="1"/>
  </joint>
  <link
    name="hand">
    <inertial>
      <origin
        xyz="3.68536599532066E-06 1.38476910288565E-05 -0.0635543718731382"
        rpy="0 0 0" />
      <xacro:inertial_matrix mass="0.05"/>
    </inertial>
    <visual>
      <origin
        xyz="0 0 0"
        rpy="0 0 0" />
      <geometry>
        <mesh
          filename="package://rm_description/meshes/hand.STL" />
      </geometry>
      <material
        name="">
        <color
          rgba="1 1 1 1" />
      </material>
    </visual>
    <collision>
      <origin
        xyz="0 0 0"
        rpy="0 0 0" />
      <geometry>
        <mesh
          filename="package://rm_description/meshes/hand.STL" />
      </geometry>
    </collision>
  </link>
  <joint
    name="hand_joint"
    type="fixed">
    <origin
      xyz="0 0 0.1"
      rpy="-1.7347E-18 2.4378E-13 -7.8121E-13" />
    <parent
      link="link6" />
    <child
      link="hand" />
    <axis
      xyz="0 0 0" />
  </joint>
  <link
    name="link7">
    <inertial>
      <origin
        xyz="1.18772258694833E-09 0 0.013272877911639"
        rpy="0 0 0" />
      <xacro:inertial_matrix mass="0.01"/>
    </inertial>
    <collision>
      <origin
        xyz="0 0 0"
        rpy="0 0 0" />
      <geometry>
        <mesh
          filename="package://rm_description/meshes/left_gripper.STL" />
      </geometry>
    </collision>
  </link>
  <joint
    name="joint7"
    type="fixed">
    <origin
      xyz="0 0 0"
      rpy="-3.4694E-18 1.7347E-18 5.5511E-17" />
    <parent
      link="hand" />
    <child
      link="link7" />
    <axis
      xyz="0 -1 0" />
    <limit
      lower="0"
      upper="0"
      effort="0"
      velocity="0" />
  </joint>
  <link
    name="left_gripper">
    <inertial>
      <origin
        xyz="1.18772258694833E-09 0 0.013272877911639"
        rpy="0 0 0" />
      <xacro:inertial_matrix mass="0.01"/>
    </inertial>
    <visual>
      <origin
        xyz="0 0 0"
        rpy="0 0 0" />
      <geometry>
        <mesh
          filename="package://rm_description/meshes/left_gripper.STL" />
      </geometry>
      <material
        name="">
        <color
          rgba="1 1 1 1" />
      </material>
    </visual>
    <collision>
      <origin
        xyz="0 0 0"
        rpy="0 0 0" />
      <geometry>
        <mesh
          filename="package://rm_description/meshes/left_gripper.STL" />
      </geometry>
    </collision>
  </link>
  <joint
    name="gripper_joint"
    type="prismatic">
    <origin
      xyz="0 0.035 0"
      rpy="-3.4694E-18 1.7347E-18 5.5511E-17" />
    <parent
      link="link7" />
    <child
      link="left_gripper" />
    <axis
      xyz="0 -1 0" />
    <limit
      lower="0"
      upper="0.035"
      effort="100"
      velocity="1" />
	<dynamics damping="50" friction="1"/>
  </joint>
  <link
    name="right_gripper">
    <inertial>
      <origin
        xyz="7.21624926480757E-10 0 0.0132728826799009"
        rpy="0 0 0" />
      <xacro:inertial_matrix mass="0.01"/>
    </inertial>
    <visual>
      <origin
        xyz="0 0 0"
        rpy="0 0 0" />
      <geometry>
        <mesh
          filename="package://rm_description/meshes/right_gripper.STL" />
      </geometry>
      <material
        name="">
        <color
          rgba="1 1 1 1" />
      </material>
    </visual>
    <collision>
      <origin
        xyz="0 0 0"
        rpy="0 0 0" />
      <geometry>
        <mesh
          filename="package://rm_description/meshes/right_gripper.STL" />
      </geometry>
    </collision>
  </link>
  <joint
    name="right_gripper_joint"
    type="prismatic">
    <origin
      xyz="0 -0.035 0"
      rpy="-3.4694E-18 1.7347E-18 5.5511E-17" />
    <parent
      link="link7" />
    <child
      link="right_gripper" />
    <axis
      xyz="0 1 0" />
    <limit
      lower="-0.035"
      upper="0"
      effort="100"
      velocity="1" />
    <mimic joint="gripper_joint"/>
	<dynamics damping="50" friction="1"/>
  </joint>
    <!-- Transmissions for ROS Control -->
    <xacro:macro name="transmission_block" params="joint_name">
        <transmission name="tran1">
            <type>transmission_interface/SimpleTransmission</type>
            <joint name="${joint_name}">
                <hardwareInterface>hardware_interface/PositionJointInterface</hardwareInterface>
            </joint>
            <actuator name="motor1">
                <hardwareInterface>hardware_interface/PositionJointInterface</hardwareInterface>
                <mechanicalReduction>1</mechanicalReduction>
            </actuator>
        </transmission>
    </xacro:macro>
    
    <xacro:transmission_block joint_name="joint1"/>
    <xacro:transmission_block joint_name="joint2"/>
    <xacro:transmission_block joint_name="joint3"/>
    <xacro:transmission_block joint_name="joint4"/>
    <xacro:transmission_block joint_name="joint5"/>
    <xacro:transmission_block joint_name="joint6"/>
    <xacro:transmission_block joint_name="gripper_joint"/>

    <!-- ros_control plugin -->
    <gazebo>
        <plugin name="gazebo_ros_control" filename="libgazebo_ros_control.so">
            <robotNamespace>/arm</robotNamespace>
        </plugin>
    </gazebo>
  </xacro:macro>
</robot>
